Internal Server Error: /auth/reset
Traceback (most recent call last):
  File "C:\Users\Nakshi\AppData\Local\Programs\Python\Python311\Lib\site-packages\django\core\handlers\exception.py", line 55, in inner
    response = get_response(request)
               ^^^^^^^^^^^^^^^^^^^^^
  File "C:\Users\Nakshi\AppData\Local\Programs\Python\Python311\Lib\site-packages\django\core\handlers\base.py", line 197, in _get_response
    response = wrapped_callback(request, *callback_args, **callback_kwargs)
               ^^^^^^^^^^^^^^^^^^^^^^^^^^^^^^^^^^^^^^^^^^^^^^^^^^^^^^^^^^^^
  File "C:\Users\Nakshi\AppData\Local\Programs\Python\Python311\Lib\site-packages\django_ratelimit\decorators.py", line 27, in _wrapped
    return fn(request, *args, **kw)
           ^^^^^^^^^^^^^^^^^^^^^^^^
  File "D:\College\Any-Time-Event-1\auth1\views.py", line 373, in reset
    return render(request, 'reset.html')
           ^^^^^^^^^^^^^^^^^^^^^^^^^^^^^
  File "C:\Users\Nakshi\AppData\Local\Programs\Python\Python311\Lib\site-packages\django\shortcuts.py", line 25, in render
    content = loader.render_to_string(template_name, context, request, using=using)
              ^^^^^^^^^^^^^^^^^^^^^^^^^^^^^^^^^^^^^^^^^^^^^^^^^^^^^^^^^^^^^^^^^^^^^
  File "C:\Users\Nakshi\AppData\Local\Programs\Python\Python311\Lib\site-packages\django\template\loader.py", line 61, in render_to_string
    template = get_template(template_name, using=using)
               ^^^^^^^^^^^^^^^^^^^^^^^^^^^^^^^^^^^^^^^^
  File "C:\Users\Nakshi\AppData\Local\Programs\Python\Python311\Lib\site-packages\django\template\loader.py", line 19, in get_template
    raise TemplateDoesNotExist(template_name, chain=chain)
django.template.exceptions.TemplateDoesNotExist: reset.html
"GET /auth/reset HTTP/1.1" 500 89451
Internal Server Error: /auth/login
Traceback (most recent call last):
  File "C:\Users\Nakshi\AppData\Local\Programs\Python\Python311\Lib\site-packages\django\db\backends\base\base.py", line 275, in ensure_connection
    self.connect()
  File "C:\Users\Nakshi\AppData\Local\Programs\Python\Python311\Lib\site-packages\django\utils\asyncio.py", line 26, in inner
    return func(*args, **kwargs)
           ^^^^^^^^^^^^^^^^^^^^^
  File "C:\Users\Nakshi\AppData\Local\Programs\Python\Python311\Lib\site-packages\django\db\backends\base\base.py", line 256, in connect
    self.connection = self.get_new_connection(conn_params)
                      ^^^^^^^^^^^^^^^^^^^^^^^^^^^^^^^^^^^^
  File "C:\Users\Nakshi\AppData\Local\Programs\Python\Python311\Lib\site-packages\django\utils\asyncio.py", line 26, in inner
    return func(*args, **kwargs)
           ^^^^^^^^^^^^^^^^^^^^^
  File "C:\Users\Nakshi\AppData\Local\Programs\Python\Python311\Lib\site-packages\django\db\backends\mysql\base.py", line 256, in get_new_connection
    connection = Database.connect(**conn_params)
                 ^^^^^^^^^^^^^^^^^^^^^^^^^^^^^^^
  File "C:\Users\Nakshi\AppData\Local\Programs\Python\Python311\Lib\site-packages\MySQLdb\__init__.py", line 121, in Connect
    return Connection(*args, **kwargs)
           ^^^^^^^^^^^^^^^^^^^^^^^^^^^
  File "C:\Users\Nakshi\AppData\Local\Programs\Python\Python311\Lib\site-packages\MySQLdb\connections.py", line 195, in __init__
    super().__init__(*args, **kwargs2)
MySQLdb.OperationalError: (2005, "Unknown server host 'anytimeevent-any-time-event.f.aivencloud.com' (11001)")

The above exception was the direct cause of the following exception:

Traceback (most recent call last):
  File "C:\Users\Nakshi\AppData\Local\Programs\Python\Python311\Lib\site-packages\django\core\handlers\exception.py", line 55, in inner
    response = get_response(request)
               ^^^^^^^^^^^^^^^^^^^^^
  File "C:\Users\Nakshi\AppData\Local\Programs\Python\Python311\Lib\site-packages\django\utils\deprecation.py", line 133, in __call__
    response = self.process_request(request)
               ^^^^^^^^^^^^^^^^^^^^^^^^^^^^^
  File "D:\College\Any-Time-Event-1\auth1\middleware.py", line 17, in process_request
    visit = Visit.objects.get(page_visited=page_visited)
            ^^^^^^^^^^^^^^^^^^^^^^^^^^^^^^^^^^^^^^^^^^^^
  File "C:\Users\Nakshi\AppData\Local\Programs\Python\Python311\Lib\site-packages\django\db\models\manager.py", line 87, in manager_method
    return getattr(self.get_queryset(), name)(*args, **kwargs)
           ^^^^^^^^^^^^^^^^^^^^^^^^^^^^^^^^^^^^^^^^^^^^^^^^^^^
  File "C:\Users\Nakshi\AppData\Local\Programs\Python\Python311\Lib\site-packages\django\db\models\query.py", line 645, in get
    num = len(clone)
          ^^^^^^^^^^
  File "C:\Users\Nakshi\AppData\Local\Programs\Python\Python311\Lib\site-packages\django\db\models\query.py", line 382, in __len__
    self._fetch_all()
  File "C:\Users\Nakshi\AppData\Local\Programs\Python\Python311\Lib\site-packages\django\db\models\query.py", line 1928, in _fetch_all
    self._result_cache = list(self._iterable_class(self))
                         ^^^^^^^^^^^^^^^^^^^^^^^^^^^^^^^^
  File "C:\Users\Nakshi\AppData\Local\Programs\Python\Python311\Lib\site-packages\django\db\models\query.py", line 91, in __iter__
    results = compiler.execute_sql(
              ^^^^^^^^^^^^^^^^^^^^^
  File "C:\Users\Nakshi\AppData\Local\Programs\Python\Python311\Lib\site-packages\django\db\models\sql\compiler.py", line 1560, in execute_sql
    cursor = self.connection.cursor()
             ^^^^^^^^^^^^^^^^^^^^^^^^
  File "C:\Users\Nakshi\AppData\Local\Programs\Python\Python311\Lib\site-packages\django\utils\asyncio.py", line 26, in inner
    return func(*args, **kwargs)
           ^^^^^^^^^^^^^^^^^^^^^
  File "C:\Users\Nakshi\AppData\Local\Programs\Python\Python311\Lib\site-packages\django\db\backends\base\base.py", line 316, in cursor
    return self._cursor()
           ^^^^^^^^^^^^^^
  File "C:\Users\Nakshi\AppData\Local\Programs\Python\Python311\Lib\site-packages\django\db\backends\base\base.py", line 292, in _cursor
    self.ensure_connection()
  File "C:\Users\Nakshi\AppData\Local\Programs\Python\Python311\Lib\site-packages\django\utils\asyncio.py", line 26, in inner
    return func(*args, **kwargs)
           ^^^^^^^^^^^^^^^^^^^^^
  File "C:\Users\Nakshi\AppData\Local\Programs\Python\Python311\Lib\site-packages\django\db\backends\base\base.py", line 274, in ensure_connection
    with self.wrap_database_errors:
  File "C:\Users\Nakshi\AppData\Local\Programs\Python\Python311\Lib\site-packages\django\db\utils.py", line 91, in __exit__
    raise dj_exc_value.with_traceback(traceback) from exc_value
  File "C:\Users\Nakshi\AppData\Local\Programs\Python\Python311\Lib\site-packages\django\db\backends\base\base.py", line 275, in ensure_connection
    self.connect()
  File "C:\Users\Nakshi\AppData\Local\Programs\Python\Python311\Lib\site-packages\django\utils\asyncio.py", line 26, in inner
    return func(*args, **kwargs)
           ^^^^^^^^^^^^^^^^^^^^^
  File "C:\Users\Nakshi\AppData\Local\Programs\Python\Python311\Lib\site-packages\django\db\backends\base\base.py", line 256, in connect
    self.connection = self.get_new_connection(conn_params)
                      ^^^^^^^^^^^^^^^^^^^^^^^^^^^^^^^^^^^^
  File "C:\Users\Nakshi\AppData\Local\Programs\Python\Python311\Lib\site-packages\django\utils\asyncio.py", line 26, in inner
    return func(*args, **kwargs)
           ^^^^^^^^^^^^^^^^^^^^^
  File "C:\Users\Nakshi\AppData\Local\Programs\Python\Python311\Lib\site-packages\django\db\backends\mysql\base.py", line 256, in get_new_connection
    connection = Database.connect(**conn_params)
                 ^^^^^^^^^^^^^^^^^^^^^^^^^^^^^^^
  File "C:\Users\Nakshi\AppData\Local\Programs\Python\Python311\Lib\site-packages\MySQLdb\__init__.py", line 121, in Connect
    return Connection(*args, **kwargs)
           ^^^^^^^^^^^^^^^^^^^^^^^^^^^
  File "C:\Users\Nakshi\AppData\Local\Programs\Python\Python311\Lib\site-packages\MySQLdb\connections.py", line 195, in __init__
    super().__init__(*args, **kwargs2)
django.db.utils.OperationalError: (2005, "Unknown server host 'anytimeevent-any-time-event.f.aivencloud.com' (11001)")
"POST /auth/login HTTP/1.1" 500 224590
