Internal Server Error: /auth/signup
Traceback (most recent call last):
  File "C:\Users\Nakshi\AppData\Local\Programs\Python\Python311\Lib\site-packages\django\core\handlers\exception.py", line 55, in inner
    response = get_response(request)
               ^^^^^^^^^^^^^^^^^^^^^
  File "C:\Users\Nakshi\AppData\Local\Programs\Python\Python311\Lib\site-packages\django\core\handlers\base.py", line 197, in _get_response
    response = wrapped_callback(request, *callback_args, **callback_kwargs)
               ^^^^^^^^^^^^^^^^^^^^^^^^^^^^^^^^^^^^^^^^^^^^^^^^^^^^^^^^^^^^
  File "C:\Users\Nakshi\AppData\Local\Programs\Python\Python311\Lib\site-packages\django_ratelimit\decorators.py", line 27, in _wrapped
    return fn(request, *args, **kw)
           ^^^^^^^^^^^^^^^^^^^^^^^^
  File "D:\College\Any-Time-Event-1\auth1\views.py", line 147, in signup
    if users.objects.all (email!=email) :
                          ^^^^^
UnboundLocalError: cannot access local variable 'email' where it is not associated with a value
"POST /auth/signup HTTP/1.1" 500 74855
Internal Server Error: /auth/signup
Traceback (most recent call last):
  File "C:\Users\Nakshi\AppData\Local\Programs\Python\Python311\Lib\site-packages\django\core\handlers\exception.py", line 55, in inner
    response = get_response(request)
               ^^^^^^^^^^^^^^^^^^^^^
  File "C:\Users\Nakshi\AppData\Local\Programs\Python\Python311\Lib\site-packages\django\core\handlers\base.py", line 197, in _get_response
    response = wrapped_callback(request, *callback_args, **callback_kwargs)
               ^^^^^^^^^^^^^^^^^^^^^^^^^^^^^^^^^^^^^^^^^^^^^^^^^^^^^^^^^^^^
  File "C:\Users\Nakshi\AppData\Local\Programs\Python\Python311\Lib\site-packages\django_ratelimit\decorators.py", line 27, in _wrapped
    return fn(request, *args, **kw)
           ^^^^^^^^^^^^^^^^^^^^^^^^
  File "D:\College\Any-Time-Event-1\auth1\views.py", line 147, in signup
    if users.objects.all (email!=email) :
                          ^^^^^
UnboundLocalError: cannot access local variable 'email' where it is not associated with a value
"POST /auth/signup HTTP/1.1" 500 74857
Internal Server Error: /auth/signup
Traceback (most recent call last):
  File "C:\Users\Nakshi\AppData\Local\Programs\Python\Python311\Lib\site-packages\django\core\handlers\exception.py", line 55, in inner
    response = get_response(request)
               ^^^^^^^^^^^^^^^^^^^^^
  File "C:\Users\Nakshi\AppData\Local\Programs\Python\Python311\Lib\site-packages\django\core\handlers\base.py", line 197, in _get_response
    response = wrapped_callback(request, *callback_args, **callback_kwargs)
               ^^^^^^^^^^^^^^^^^^^^^^^^^^^^^^^^^^^^^^^^^^^^^^^^^^^^^^^^^^^^
  File "C:\Users\Nakshi\AppData\Local\Programs\Python\Python311\Lib\site-packages\django_ratelimit\decorators.py", line 27, in _wrapped
    return fn(request, *args, **kw)
           ^^^^^^^^^^^^^^^^^^^^^^^^
  File "D:\College\Any-Time-Event-1\auth1\views.py", line 147, in signup
    if users.objects.all (email!=email) :
                          ^^^^^
UnboundLocalError: cannot access local variable 'email' where it is not associated with a value
"POST /auth/signup HTTP/1.1" 500 74855
Internal Server Error: /auth/signup
Traceback (most recent call last):
  File "C:\Users\Nakshi\AppData\Local\Programs\Python\Python311\Lib\site-packages\django\core\handlers\exception.py", line 55, in inner
    response = get_response(request)
               ^^^^^^^^^^^^^^^^^^^^^
  File "C:\Users\Nakshi\AppData\Local\Programs\Python\Python311\Lib\site-packages\django\core\handlers\base.py", line 197, in _get_response
    response = wrapped_callback(request, *callback_args, **callback_kwargs)
               ^^^^^^^^^^^^^^^^^^^^^^^^^^^^^^^^^^^^^^^^^^^^^^^^^^^^^^^^^^^^
  File "C:\Users\Nakshi\AppData\Local\Programs\Python\Python311\Lib\site-packages\django_ratelimit\decorators.py", line 27, in _wrapped
    return fn(request, *args, **kw)
           ^^^^^^^^^^^^^^^^^^^^^^^^
  File "D:\College\Any-Time-Event-1\auth1\views.py", line 144, in signup
    if users.objects.all (email!=email) :
                          ^^^^^
UnboundLocalError: cannot access local variable 'email' where it is not associated with a value
"POST /auth/signup HTTP/1.1" 500 74807
Internal Server Error: /auth/signup
Traceback (most recent call last):
  File "C:\Users\Nakshi\AppData\Local\Programs\Python\Python311\Lib\site-packages\django\core\handlers\exception.py", line 55, in inner
    response = get_response(request)
               ^^^^^^^^^^^^^^^^^^^^^
  File "C:\Users\Nakshi\AppData\Local\Programs\Python\Python311\Lib\site-packages\django\core\handlers\base.py", line 197, in _get_response
    response = wrapped_callback(request, *callback_args, **callback_kwargs)
               ^^^^^^^^^^^^^^^^^^^^^^^^^^^^^^^^^^^^^^^^^^^^^^^^^^^^^^^^^^^^
  File "C:\Users\Nakshi\AppData\Local\Programs\Python\Python311\Lib\site-packages\django_ratelimit\decorators.py", line 27, in _wrapped
    return fn(request, *args, **kw)
           ^^^^^^^^^^^^^^^^^^^^^^^^
  File "D:\College\Any-Time-Event-1\auth1\views.py", line 144, in signup
    if users.objects.all (email!=email) :
                          ^^^^^
UnboundLocalError: cannot access local variable 'email' where it is not associated with a value
"POST /auth/signup HTTP/1.1" 500 74807
Internal Server Error: /auth/signup
Traceback (most recent call last):
  File "C:\Users\Nakshi\AppData\Local\Programs\Python\Python311\Lib\site-packages\django\core\handlers\exception.py", line 55, in inner
    response = get_response(request)
               ^^^^^^^^^^^^^^^^^^^^^
  File "C:\Users\Nakshi\AppData\Local\Programs\Python\Python311\Lib\site-packages\django\core\handlers\base.py", line 197, in _get_response
    response = wrapped_callback(request, *callback_args, **callback_kwargs)
               ^^^^^^^^^^^^^^^^^^^^^^^^^^^^^^^^^^^^^^^^^^^^^^^^^^^^^^^^^^^^
  File "C:\Users\Nakshi\AppData\Local\Programs\Python\Python311\Lib\site-packages\django_ratelimit\decorators.py", line 27, in _wrapped
    return fn(request, *args, **kw)
           ^^^^^^^^^^^^^^^^^^^^^^^^
  File "D:\College\Any-Time-Event-1\auth1\views.py", line 145, in signup
    if users.objects.all (email!=email) :
       ^^^^^^^^^^^^^^^^^^^^^^^^^^^^^^^^
TypeError: BaseManager.all() takes 1 positional argument but 2 were given
"POST /auth/signup HTTP/1.1" 500 74981
Internal Server Error: /auth/signup
Traceback (most recent call last):
  File "C:\Users\Nakshi\AppData\Local\Programs\Python\Python311\Lib\site-packages\django\core\handlers\exception.py", line 55, in inner
    response = get_response(request)
               ^^^^^^^^^^^^^^^^^^^^^
  File "C:\Users\Nakshi\AppData\Local\Programs\Python\Python311\Lib\site-packages\django\core\handlers\base.py", line 197, in _get_response
    response = wrapped_callback(request, *callback_args, **callback_kwargs)
               ^^^^^^^^^^^^^^^^^^^^^^^^^^^^^^^^^^^^^^^^^^^^^^^^^^^^^^^^^^^^
  File "C:\Users\Nakshi\AppData\Local\Programs\Python\Python311\Lib\site-packages\django_ratelimit\decorators.py", line 27, in _wrapped
    return fn(request, *args, **kw)
           ^^^^^^^^^^^^^^^^^^^^^^^^
  File "D:\College\Any-Time-Event-1\auth1\views.py", line 166, in signup
    user1 = users(email=email,password=encrypted_password,key=key_str,role=role)
            ^^^^^^^^^^^^^^^^^^^^^^^^^^^^^^^^^^^^^^^^^^^^^^^^^^^^^^^^^^^^^^^^^^^^
  File "C:\Users\Nakshi\AppData\Local\Programs\Python\Python311\Lib\site-packages\django\db\models\base.py", line 567, in __init__
    raise TypeError(
TypeError: users() got unexpected keyword arguments: 'role'
Internal Server Error: /auth/signup
Traceback (most recent call last):
  File "C:\Users\Nakshi\AppData\Local\Programs\Python\Python311\Lib\site-packages\django\core\handlers\exception.py", line 55, in inner
    response = get_response(request)
               ^^^^^^^^^^^^^^^^^^^^^
  File "C:\Users\Nakshi\AppData\Local\Programs\Python\Python311\Lib\site-packages\django\core\handlers\base.py", line 197, in _get_response
    response = wrapped_callback(request, *callback_args, **callback_kwargs)
               ^^^^^^^^^^^^^^^^^^^^^^^^^^^^^^^^^^^^^^^^^^^^^^^^^^^^^^^^^^^^
  File "C:\Users\Nakshi\AppData\Local\Programs\Python\Python311\Lib\site-packages\django_ratelimit\decorators.py", line 27, in _wrapped
    return fn(request, *args, **kw)
           ^^^^^^^^^^^^^^^^^^^^^^^^
  File "D:\College\Any-Time-Event-1\auth1\views.py", line 166, in signup
    user1 = users(email=email,password=encrypted_password,key=key_str,role=role)
            ^^^^^^^^^^^^^^^^^^^^^^^^^^^^^^^^^^^^^^^^^^^^^^^^^^^^^^^^^^^^^^^^^^^^
  File "C:\Users\Nakshi\AppData\Local\Programs\Python\Python311\Lib\site-packages\django\db\models\base.py", line 567, in __init__
    raise TypeError(
TypeError: users() got unexpected keyword arguments: 'role'
"POST /auth/signup HTTP/1.1" 500 84092
Internal Server Error: /auth/signup
Traceback (most recent call last):
  File "C:\Users\Nakshi\AppData\Local\Programs\Python\Python311\Lib\site-packages\django\db\backends\utils.py", line 105, in _execute
    return self.cursor.execute(sql, params)
           ^^^^^^^^^^^^^^^^^^^^^^^^^^^^^^^^
  File "C:\Users\Nakshi\AppData\Local\Programs\Python\Python311\Lib\site-packages\django\db\backends\mysql\base.py", line 76, in execute
    return self.cursor.execute(query, args)
           ^^^^^^^^^^^^^^^^^^^^^^^^^^^^^^^^
  File "C:\Users\Nakshi\AppData\Local\Programs\Python\Python311\Lib\site-packages\MySQLdb\cursors.py", line 179, in execute
    res = self._query(mogrified_query)
          ^^^^^^^^^^^^^^^^^^^^^^^^^^^^
  File "C:\Users\Nakshi\AppData\Local\Programs\Python\Python311\Lib\site-packages\MySQLdb\cursors.py", line 330, in _query
    db.query(q)
  File "C:\Users\Nakshi\AppData\Local\Programs\Python\Python311\Lib\site-packages\MySQLdb\connections.py", line 261, in query
    _mysql.connection.query(self, query)
MySQLdb.OperationalError: (1054, "Unknown column 'role' in 'field list'")

The above exception was the direct cause of the following exception:

Traceback (most recent call last):
  File "C:\Users\Nakshi\AppData\Local\Programs\Python\Python311\Lib\site-packages\django\core\handlers\exception.py", line 55, in inner
    response = get_response(request)
               ^^^^^^^^^^^^^^^^^^^^^
  File "C:\Users\Nakshi\AppData\Local\Programs\Python\Python311\Lib\site-packages\django\core\handlers\base.py", line 197, in _get_response
    response = wrapped_callback(request, *callback_args, **callback_kwargs)
               ^^^^^^^^^^^^^^^^^^^^^^^^^^^^^^^^^^^^^^^^^^^^^^^^^^^^^^^^^^^^
  File "C:\Users\Nakshi\AppData\Local\Programs\Python\Python311\Lib\site-packages\django_ratelimit\decorators.py", line 27, in _wrapped
    return fn(request, *args, **kw)
           ^^^^^^^^^^^^^^^^^^^^^^^^
  File "D:\College\Any-Time-Event-1\auth1\views.py", line 167, in signup
    user1.save()
  File "C:\Users\Nakshi\AppData\Local\Programs\Python\Python311\Lib\site-packages\django\db\models\base.py", line 822, in save
    self.save_base(
  File "C:\Users\Nakshi\AppData\Local\Programs\Python\Python311\Lib\site-packages\django\db\models\base.py", line 909, in save_base
    updated = self._save_table(
              ^^^^^^^^^^^^^^^^^
  File "C:\Users\Nakshi\AppData\Local\Programs\Python\Python311\Lib\site-packages\django\db\models\base.py", line 1071, in _save_table
    results = self._do_insert(
              ^^^^^^^^^^^^^^^^
  File "C:\Users\Nakshi\AppData\Local\Programs\Python\Python311\Lib\site-packages\django\db\models\base.py", line 1112, in _do_insert
    return manager._insert(
           ^^^^^^^^^^^^^^^^
  File "C:\Users\Nakshi\AppData\Local\Programs\Python\Python311\Lib\site-packages\django\db\models\manager.py", line 87, in manager_method
    return getattr(self.get_queryset(), name)(*args, **kwargs)
           ^^^^^^^^^^^^^^^^^^^^^^^^^^^^^^^^^^^^^^^^^^^^^^^^^^^
  File "C:\Users\Nakshi\AppData\Local\Programs\Python\Python311\Lib\site-packages\django\db\models\query.py", line 1847, in _insert
    return query.get_compiler(using=using).execute_sql(returning_fields)
           ^^^^^^^^^^^^^^^^^^^^^^^^^^^^^^^^^^^^^^^^^^^^^^^^^^^^^^^^^^^^^
  File "C:\Users\Nakshi\AppData\Local\Programs\Python\Python311\Lib\site-packages\django\db\models\sql\compiler.py", line 1823, in execute_sql
    cursor.execute(sql, params)
  File "C:\Users\Nakshi\AppData\Local\Programs\Python\Python311\Lib\site-packages\django\db\backends\utils.py", line 122, in execute
    return super().execute(sql, params)
           ^^^^^^^^^^^^^^^^^^^^^^^^^^^^
  File "C:\Users\Nakshi\AppData\Local\Programs\Python\Python311\Lib\site-packages\django\db\backends\utils.py", line 79, in execute
    return self._execute_with_wrappers(
           ^^^^^^^^^^^^^^^^^^^^^^^^^^^^
  File "C:\Users\Nakshi\AppData\Local\Programs\Python\Python311\Lib\site-packages\django\db\backends\utils.py", line 92, in _execute_with_wrappers
    return executor(sql, params, many, context)
           ^^^^^^^^^^^^^^^^^^^^^^^^^^^^^^^^^^^^
  File "C:\Users\Nakshi\AppData\Local\Programs\Python\Python311\Lib\site-packages\django\db\backends\utils.py", line 100, in _execute
    with self.db.wrap_database_errors:
  File "C:\Users\Nakshi\AppData\Local\Programs\Python\Python311\Lib\site-packages\django\db\utils.py", line 91, in __exit__
    raise dj_exc_value.with_traceback(traceback) from exc_value
  File "C:\Users\Nakshi\AppData\Local\Programs\Python\Python311\Lib\site-packages\django\db\backends\utils.py", line 105, in _execute
    return self.cursor.execute(sql, params)
           ^^^^^^^^^^^^^^^^^^^^^^^^^^^^^^^^
  File "C:\Users\Nakshi\AppData\Local\Programs\Python\Python311\Lib\site-packages\django\db\backends\mysql\base.py", line 76, in execute
    return self.cursor.execute(query, args)
           ^^^^^^^^^^^^^^^^^^^^^^^^^^^^^^^^
  File "C:\Users\Nakshi\AppData\Local\Programs\Python\Python311\Lib\site-packages\MySQLdb\cursors.py", line 179, in execute
    res = self._query(mogrified_query)
          ^^^^^^^^^^^^^^^^^^^^^^^^^^^^
  File "C:\Users\Nakshi\AppData\Local\Programs\Python\Python311\Lib\site-packages\MySQLdb\cursors.py", line 330, in _query
    db.query(q)
  File "C:\Users\Nakshi\AppData\Local\Programs\Python\Python311\Lib\site-packages\MySQLdb\connections.py", line 261, in query
    _mysql.connection.query(self, query)
django.db.utils.OperationalError: (1054, "Unknown column 'role' in 'field list'")
"POST /auth/signup HTTP/1.1" 500 185956
Internal Server Error: /auth/signup
Traceback (most recent call last):
  File "C:\Users\Nakshi\AppData\Local\Programs\Python\Python311\Lib\site-packages\django\db\backends\utils.py", line 105, in _execute
    return self.cursor.execute(sql, params)
           ^^^^^^^^^^^^^^^^^^^^^^^^^^^^^^^^
  File "C:\Users\Nakshi\AppData\Local\Programs\Python\Python311\Lib\site-packages\django\db\backends\mysql\base.py", line 76, in execute
    return self.cursor.execute(query, args)
           ^^^^^^^^^^^^^^^^^^^^^^^^^^^^^^^^
  File "C:\Users\Nakshi\AppData\Local\Programs\Python\Python311\Lib\site-packages\MySQLdb\cursors.py", line 179, in execute
    res = self._query(mogrified_query)
          ^^^^^^^^^^^^^^^^^^^^^^^^^^^^
  File "C:\Users\Nakshi\AppData\Local\Programs\Python\Python311\Lib\site-packages\MySQLdb\cursors.py", line 330, in _query
    db.query(q)
  File "C:\Users\Nakshi\AppData\Local\Programs\Python\Python311\Lib\site-packages\MySQLdb\connections.py", line 261, in query
    _mysql.connection.query(self, query)
MySQLdb.OperationalError: (1054, "Unknown column 'role' in 'field list'")

The above exception was the direct cause of the following exception:

Traceback (most recent call last):
  File "C:\Users\Nakshi\AppData\Local\Programs\Python\Python311\Lib\site-packages\django\core\handlers\exception.py", line 55, in inner
    response = get_response(request)
               ^^^^^^^^^^^^^^^^^^^^^
  File "C:\Users\Nakshi\AppData\Local\Programs\Python\Python311\Lib\site-packages\django\core\handlers\base.py", line 197, in _get_response
    response = wrapped_callback(request, *callback_args, **callback_kwargs)
               ^^^^^^^^^^^^^^^^^^^^^^^^^^^^^^^^^^^^^^^^^^^^^^^^^^^^^^^^^^^^
  File "C:\Users\Nakshi\AppData\Local\Programs\Python\Python311\Lib\site-packages\django_ratelimit\decorators.py", line 27, in _wrapped
    return fn(request, *args, **kw)
           ^^^^^^^^^^^^^^^^^^^^^^^^
  File "D:\College\Any-Time-Event-1\auth1\views.py", line 167, in signup
    user1.save()
  File "C:\Users\Nakshi\AppData\Local\Programs\Python\Python311\Lib\site-packages\django\db\models\base.py", line 822, in save
    self.save_base(
  File "C:\Users\Nakshi\AppData\Local\Programs\Python\Python311\Lib\site-packages\django\db\models\base.py", line 909, in save_base
    updated = self._save_table(
              ^^^^^^^^^^^^^^^^^
  File "C:\Users\Nakshi\AppData\Local\Programs\Python\Python311\Lib\site-packages\django\db\models\base.py", line 1071, in _save_table
    results = self._do_insert(
              ^^^^^^^^^^^^^^^^
  File "C:\Users\Nakshi\AppData\Local\Programs\Python\Python311\Lib\site-packages\django\db\models\base.py", line 1112, in _do_insert
    return manager._insert(
           ^^^^^^^^^^^^^^^^
  File "C:\Users\Nakshi\AppData\Local\Programs\Python\Python311\Lib\site-packages\django\db\models\manager.py", line 87, in manager_method
    return getattr(self.get_queryset(), name)(*args, **kwargs)
           ^^^^^^^^^^^^^^^^^^^^^^^^^^^^^^^^^^^^^^^^^^^^^^^^^^^
  File "C:\Users\Nakshi\AppData\Local\Programs\Python\Python311\Lib\site-packages\django\db\models\query.py", line 1847, in _insert
    return query.get_compiler(using=using).execute_sql(returning_fields)
           ^^^^^^^^^^^^^^^^^^^^^^^^^^^^^^^^^^^^^^^^^^^^^^^^^^^^^^^^^^^^^
  File "C:\Users\Nakshi\AppData\Local\Programs\Python\Python311\Lib\site-packages\django\db\models\sql\compiler.py", line 1823, in execute_sql
    cursor.execute(sql, params)
  File "C:\Users\Nakshi\AppData\Local\Programs\Python\Python311\Lib\site-packages\django\db\backends\utils.py", line 122, in execute
    return super().execute(sql, params)
           ^^^^^^^^^^^^^^^^^^^^^^^^^^^^
  File "C:\Users\Nakshi\AppData\Local\Programs\Python\Python311\Lib\site-packages\django\db\backends\utils.py", line 79, in execute
    return self._execute_with_wrappers(
           ^^^^^^^^^^^^^^^^^^^^^^^^^^^^
  File "C:\Users\Nakshi\AppData\Local\Programs\Python\Python311\Lib\site-packages\django\db\backends\utils.py", line 92, in _execute_with_wrappers
    return executor(sql, params, many, context)
           ^^^^^^^^^^^^^^^^^^^^^^^^^^^^^^^^^^^^
  File "C:\Users\Nakshi\AppData\Local\Programs\Python\Python311\Lib\site-packages\django\db\backends\utils.py", line 100, in _execute
    with self.db.wrap_database_errors:
  File "C:\Users\Nakshi\AppData\Local\Programs\Python\Python311\Lib\site-packages\django\db\utils.py", line 91, in __exit__
    raise dj_exc_value.with_traceback(traceback) from exc_value
  File "C:\Users\Nakshi\AppData\Local\Programs\Python\Python311\Lib\site-packages\django\db\backends\utils.py", line 105, in _execute
    return self.cursor.execute(sql, params)
           ^^^^^^^^^^^^^^^^^^^^^^^^^^^^^^^^
  File "C:\Users\Nakshi\AppData\Local\Programs\Python\Python311\Lib\site-packages\django\db\backends\mysql\base.py", line 76, in execute
    return self.cursor.execute(query, args)
           ^^^^^^^^^^^^^^^^^^^^^^^^^^^^^^^^
  File "C:\Users\Nakshi\AppData\Local\Programs\Python\Python311\Lib\site-packages\MySQLdb\cursors.py", line 179, in execute
    res = self._query(mogrified_query)
          ^^^^^^^^^^^^^^^^^^^^^^^^^^^^
  File "C:\Users\Nakshi\AppData\Local\Programs\Python\Python311\Lib\site-packages\MySQLdb\cursors.py", line 330, in _query
    db.query(q)
  File "C:\Users\Nakshi\AppData\Local\Programs\Python\Python311\Lib\site-packages\MySQLdb\connections.py", line 261, in query
    _mysql.connection.query(self, query)
django.db.utils.OperationalError: (1054, "Unknown column 'role' in 'field list'")
"POST /auth/signup HTTP/1.1" 500 185956
Internal Server Error: /auth/signup
Traceback (most recent call last):
  File "C:\Users\Nakshi\AppData\Local\Programs\Python\Python311\Lib\site-packages\django\db\backends\utils.py", line 105, in _execute
    return self.cursor.execute(sql, params)
           ^^^^^^^^^^^^^^^^^^^^^^^^^^^^^^^^
  File "C:\Users\Nakshi\AppData\Local\Programs\Python\Python311\Lib\site-packages\django\db\backends\mysql\base.py", line 76, in execute
    return self.cursor.execute(query, args)
           ^^^^^^^^^^^^^^^^^^^^^^^^^^^^^^^^
  File "C:\Users\Nakshi\AppData\Local\Programs\Python\Python311\Lib\site-packages\MySQLdb\cursors.py", line 179, in execute
    res = self._query(mogrified_query)
          ^^^^^^^^^^^^^^^^^^^^^^^^^^^^
  File "C:\Users\Nakshi\AppData\Local\Programs\Python\Python311\Lib\site-packages\MySQLdb\cursors.py", line 330, in _query
    db.query(q)
  File "C:\Users\Nakshi\AppData\Local\Programs\Python\Python311\Lib\site-packages\MySQLdb\connections.py", line 261, in query
    _mysql.connection.query(self, query)
MySQLdb.OperationalError: (1054, "Unknown column 'role' in 'field list'")

The above exception was the direct cause of the following exception:

Traceback (most recent call last):
  File "C:\Users\Nakshi\AppData\Local\Programs\Python\Python311\Lib\site-packages\django\core\handlers\exception.py", line 55, in inner
    response = get_response(request)
               ^^^^^^^^^^^^^^^^^^^^^
  File "C:\Users\Nakshi\AppData\Local\Programs\Python\Python311\Lib\site-packages\django\core\handlers\base.py", line 197, in _get_response
    response = wrapped_callback(request, *callback_args, **callback_kwargs)
               ^^^^^^^^^^^^^^^^^^^^^^^^^^^^^^^^^^^^^^^^^^^^^^^^^^^^^^^^^^^^
  File "C:\Users\Nakshi\AppData\Local\Programs\Python\Python311\Lib\site-packages\django_ratelimit\decorators.py", line 27, in _wrapped
    return fn(request, *args, **kw)
           ^^^^^^^^^^^^^^^^^^^^^^^^
  File "D:\College\Any-Time-Event-1\auth1\views.py", line 167, in signup
    user1.save()
  File "C:\Users\Nakshi\AppData\Local\Programs\Python\Python311\Lib\site-packages\django\db\models\base.py", line 822, in save
    self.save_base(
  File "C:\Users\Nakshi\AppData\Local\Programs\Python\Python311\Lib\site-packages\django\db\models\base.py", line 909, in save_base
    updated = self._save_table(
              ^^^^^^^^^^^^^^^^^
  File "C:\Users\Nakshi\AppData\Local\Programs\Python\Python311\Lib\site-packages\django\db\models\base.py", line 1071, in _save_table
    results = self._do_insert(
              ^^^^^^^^^^^^^^^^
  File "C:\Users\Nakshi\AppData\Local\Programs\Python\Python311\Lib\site-packages\django\db\models\base.py", line 1112, in _do_insert
    return manager._insert(
           ^^^^^^^^^^^^^^^^
  File "C:\Users\Nakshi\AppData\Local\Programs\Python\Python311\Lib\site-packages\django\db\models\manager.py", line 87, in manager_method
    return getattr(self.get_queryset(), name)(*args, **kwargs)
           ^^^^^^^^^^^^^^^^^^^^^^^^^^^^^^^^^^^^^^^^^^^^^^^^^^^
  File "C:\Users\Nakshi\AppData\Local\Programs\Python\Python311\Lib\site-packages\django\db\models\query.py", line 1847, in _insert
    return query.get_compiler(using=using).execute_sql(returning_fields)
           ^^^^^^^^^^^^^^^^^^^^^^^^^^^^^^^^^^^^^^^^^^^^^^^^^^^^^^^^^^^^^
  File "C:\Users\Nakshi\AppData\Local\Programs\Python\Python311\Lib\site-packages\django\db\models\sql\compiler.py", line 1823, in execute_sql
    cursor.execute(sql, params)
  File "C:\Users\Nakshi\AppData\Local\Programs\Python\Python311\Lib\site-packages\django\db\backends\utils.py", line 122, in execute
    return super().execute(sql, params)
           ^^^^^^^^^^^^^^^^^^^^^^^^^^^^
  File "C:\Users\Nakshi\AppData\Local\Programs\Python\Python311\Lib\site-packages\django\db\backends\utils.py", line 79, in execute
    return self._execute_with_wrappers(
           ^^^^^^^^^^^^^^^^^^^^^^^^^^^^
  File "C:\Users\Nakshi\AppData\Local\Programs\Python\Python311\Lib\site-packages\django\db\backends\utils.py", line 92, in _execute_with_wrappers
    return executor(sql, params, many, context)
           ^^^^^^^^^^^^^^^^^^^^^^^^^^^^^^^^^^^^
  File "C:\Users\Nakshi\AppData\Local\Programs\Python\Python311\Lib\site-packages\django\db\backends\utils.py", line 100, in _execute
    with self.db.wrap_database_errors:
  File "C:\Users\Nakshi\AppData\Local\Programs\Python\Python311\Lib\site-packages\django\db\utils.py", line 91, in __exit__
    raise dj_exc_value.with_traceback(traceback) from exc_value
  File "C:\Users\Nakshi\AppData\Local\Programs\Python\Python311\Lib\site-packages\django\db\backends\utils.py", line 105, in _execute
    return self.cursor.execute(sql, params)
           ^^^^^^^^^^^^^^^^^^^^^^^^^^^^^^^^
  File "C:\Users\Nakshi\AppData\Local\Programs\Python\Python311\Lib\site-packages\django\db\backends\mysql\base.py", line 76, in execute
    return self.cursor.execute(query, args)
           ^^^^^^^^^^^^^^^^^^^^^^^^^^^^^^^^
  File "C:\Users\Nakshi\AppData\Local\Programs\Python\Python311\Lib\site-packages\MySQLdb\cursors.py", line 179, in execute
    res = self._query(mogrified_query)
          ^^^^^^^^^^^^^^^^^^^^^^^^^^^^
  File "C:\Users\Nakshi\AppData\Local\Programs\Python\Python311\Lib\site-packages\MySQLdb\cursors.py", line 330, in _query
    db.query(q)
  File "C:\Users\Nakshi\AppData\Local\Programs\Python\Python311\Lib\site-packages\MySQLdb\connections.py", line 261, in query
    _mysql.connection.query(self, query)
django.db.utils.OperationalError: (1054, "Unknown column 'role' in 'field list'")
"POST /auth/signup HTTP/1.1" 500 185991
