Internal Server Error: /auth/reset
Traceback (most recent call last):
  File "C:\Users\Nakshi\AppData\Local\Programs\Python\Python311\Lib\site-packages\django\core\handlers\exception.py", line 55, in inner
    response = get_response(request)
               ^^^^^^^^^^^^^^^^^^^^^
  File "C:\Users\Nakshi\AppData\Local\Programs\Python\Python311\Lib\site-packages\django\core\handlers\base.py", line 197, in _get_response
    response = wrapped_callback(request, *callback_args, **callback_kwargs)
               ^^^^^^^^^^^^^^^^^^^^^^^^^^^^^^^^^^^^^^^^^^^^^^^^^^^^^^^^^^^^
  File "C:\Users\Nakshi\AppData\Local\Programs\Python\Python311\Lib\site-packages\django_ratelimit\decorators.py", line 27, in _wrapped
    return fn(request, *args, **kw)
           ^^^^^^^^^^^^^^^^^^^^^^^^
  File "D:\College\Any-Time-Event-1\auth1\views.py", line 373, in reset
    return render(request, 'reset.html')
           ^^^^^^^^^^^^^^^^^^^^^^^^^^^^^
  File "C:\Users\Nakshi\AppData\Local\Programs\Python\Python311\Lib\site-packages\django\shortcuts.py", line 25, in render
    content = loader.render_to_string(template_name, context, request, using=using)
              ^^^^^^^^^^^^^^^^^^^^^^^^^^^^^^^^^^^^^^^^^^^^^^^^^^^^^^^^^^^^^^^^^^^^^
  File "C:\Users\Nakshi\AppData\Local\Programs\Python\Python311\Lib\site-packages\django\template\loader.py", line 61, in render_to_string
    template = get_template(template_name, using=using)
               ^^^^^^^^^^^^^^^^^^^^^^^^^^^^^^^^^^^^^^^^
  File "C:\Users\Nakshi\AppData\Local\Programs\Python\Python311\Lib\site-packages\django\template\loader.py", line 19, in get_template
    raise TemplateDoesNotExist(template_name, chain=chain)
django.template.exceptions.TemplateDoesNotExist: reset.html
"GET /auth/reset HTTP/1.1" 500 89451
Internal Server Error: /auth/login
Traceback (most recent call last):
  File "C:\Users\Nakshi\AppData\Local\Programs\Python\Python311\Lib\site-packages\django\db\backends\base\base.py", line 275, in ensure_connection
    self.connect()
  File "C:\Users\Nakshi\AppData\Local\Programs\Python\Python311\Lib\site-packages\django\utils\asyncio.py", line 26, in inner
    return func(*args, **kwargs)
           ^^^^^^^^^^^^^^^^^^^^^
  File "C:\Users\Nakshi\AppData\Local\Programs\Python\Python311\Lib\site-packages\django\db\backends\base\base.py", line 256, in connect
    self.connection = self.get_new_connection(conn_params)
                      ^^^^^^^^^^^^^^^^^^^^^^^^^^^^^^^^^^^^
  File "C:\Users\Nakshi\AppData\Local\Programs\Python\Python311\Lib\site-packages\django\utils\asyncio.py", line 26, in inner
    return func(*args, **kwargs)
           ^^^^^^^^^^^^^^^^^^^^^
  File "C:\Users\Nakshi\AppData\Local\Programs\Python\Python311\Lib\site-packages\django\db\backends\mysql\base.py", line 256, in get_new_connection
    connection = Database.connect(**conn_params)
                 ^^^^^^^^^^^^^^^^^^^^^^^^^^^^^^^
  File "C:\Users\Nakshi\AppData\Local\Programs\Python\Python311\Lib\site-packages\MySQLdb\__init__.py", line 121, in Connect
    return Connection(*args, **kwargs)
           ^^^^^^^^^^^^^^^^^^^^^^^^^^^
  File "C:\Users\Nakshi\AppData\Local\Programs\Python\Python311\Lib\site-packages\MySQLdb\connections.py", line 195, in __init__
    super().__init__(*args, **kwargs2)
MySQLdb.OperationalError: (2005, "Unknown server host 'anytimeevent-any-time-event.f.aivencloud.com' (11001)")

The above exception was the direct cause of the following exception:

Traceback (most recent call last):
  File "C:\Users\Nakshi\AppData\Local\Programs\Python\Python311\Lib\site-packages\django\core\handlers\exception.py", line 55, in inner
    response = get_response(request)
               ^^^^^^^^^^^^^^^^^^^^^
  File "C:\Users\Nakshi\AppData\Local\Programs\Python\Python311\Lib\site-packages\django\utils\deprecation.py", line 133, in __call__
    response = self.process_request(request)
               ^^^^^^^^^^^^^^^^^^^^^^^^^^^^^
  File "D:\College\Any-Time-Event-1\auth1\middleware.py", line 17, in process_request
    visit = Visit.objects.get(page_visited=page_visited)
            ^^^^^^^^^^^^^^^^^^^^^^^^^^^^^^^^^^^^^^^^^^^^
  File "C:\Users\Nakshi\AppData\Local\Programs\Python\Python311\Lib\site-packages\django\db\models\manager.py", line 87, in manager_method
    return getattr(self.get_queryset(), name)(*args, **kwargs)
           ^^^^^^^^^^^^^^^^^^^^^^^^^^^^^^^^^^^^^^^^^^^^^^^^^^^
  File "C:\Users\Nakshi\AppData\Local\Programs\Python\Python311\Lib\site-packages\django\db\models\query.py", line 645, in get
    num = len(clone)
          ^^^^^^^^^^
  File "C:\Users\Nakshi\AppData\Local\Programs\Python\Python311\Lib\site-packages\django\db\models\query.py", line 382, in __len__
    self._fetch_all()
  File "C:\Users\Nakshi\AppData\Local\Programs\Python\Python311\Lib\site-packages\django\db\models\query.py", line 1928, in _fetch_all
    self._result_cache = list(self._iterable_class(self))
                         ^^^^^^^^^^^^^^^^^^^^^^^^^^^^^^^^
  File "C:\Users\Nakshi\AppData\Local\Programs\Python\Python311\Lib\site-packages\django\db\models\query.py", line 91, in __iter__
    results = compiler.execute_sql(
              ^^^^^^^^^^^^^^^^^^^^^
  File "C:\Users\Nakshi\AppData\Local\Programs\Python\Python311\Lib\site-packages\django\db\models\sql\compiler.py", line 1560, in execute_sql
    cursor = self.connection.cursor()
             ^^^^^^^^^^^^^^^^^^^^^^^^
  File "C:\Users\Nakshi\AppData\Local\Programs\Python\Python311\Lib\site-packages\django\utils\asyncio.py", line 26, in inner
    return func(*args, **kwargs)
           ^^^^^^^^^^^^^^^^^^^^^
  File "C:\Users\Nakshi\AppData\Local\Programs\Python\Python311\Lib\site-packages\django\db\backends\base\base.py", line 316, in cursor
    return self._cursor()
           ^^^^^^^^^^^^^^
  File "C:\Users\Nakshi\AppData\Local\Programs\Python\Python311\Lib\site-packages\django\db\backends\base\base.py", line 292, in _cursor
    self.ensure_connection()
  File "C:\Users\Nakshi\AppData\Local\Programs\Python\Python311\Lib\site-packages\django\utils\asyncio.py", line 26, in inner
    return func(*args, **kwargs)
           ^^^^^^^^^^^^^^^^^^^^^
  File "C:\Users\Nakshi\AppData\Local\Programs\Python\Python311\Lib\site-packages\django\db\backends\base\base.py", line 274, in ensure_connection
    with self.wrap_database_errors:
  File "C:\Users\Nakshi\AppData\Local\Programs\Python\Python311\Lib\site-packages\django\db\utils.py", line 91, in __exit__
    raise dj_exc_value.with_traceback(traceback) from exc_value
  File "C:\Users\Nakshi\AppData\Local\Programs\Python\Python311\Lib\site-packages\django\db\backends\base\base.py", line 275, in ensure_connection
    self.connect()
  File "C:\Users\Nakshi\AppData\Local\Programs\Python\Python311\Lib\site-packages\django\utils\asyncio.py", line 26, in inner
    return func(*args, **kwargs)
           ^^^^^^^^^^^^^^^^^^^^^
  File "C:\Users\Nakshi\AppData\Local\Programs\Python\Python311\Lib\site-packages\django\db\backends\base\base.py", line 256, in connect
    self.connection = self.get_new_connection(conn_params)
                      ^^^^^^^^^^^^^^^^^^^^^^^^^^^^^^^^^^^^
  File "C:\Users\Nakshi\AppData\Local\Programs\Python\Python311\Lib\site-packages\django\utils\asyncio.py", line 26, in inner
    return func(*args, **kwargs)
           ^^^^^^^^^^^^^^^^^^^^^
  File "C:\Users\Nakshi\AppData\Local\Programs\Python\Python311\Lib\site-packages\django\db\backends\mysql\base.py", line 256, in get_new_connection
    connection = Database.connect(**conn_params)
                 ^^^^^^^^^^^^^^^^^^^^^^^^^^^^^^^
  File "C:\Users\Nakshi\AppData\Local\Programs\Python\Python311\Lib\site-packages\MySQLdb\__init__.py", line 121, in Connect
    return Connection(*args, **kwargs)
           ^^^^^^^^^^^^^^^^^^^^^^^^^^^
  File "C:\Users\Nakshi\AppData\Local\Programs\Python\Python311\Lib\site-packages\MySQLdb\connections.py", line 195, in __init__
    super().__init__(*args, **kwargs2)
django.db.utils.OperationalError: (2005, "Unknown server host 'anytimeevent-any-time-event.f.aivencloud.com' (11001)")
"POST /auth/login HTTP/1.1" 500 224590
Internal Server Error: /auth/reset
Traceback (most recent call last):
  File "C:\Users\dpsha\AppData\Roaming\Python\Python312\site-packages\django\core\handlers\exception.py", line 55, in inner
    response = get_response(request)
               ^^^^^^^^^^^^^^^^^^^^^
  File "C:\Users\dpsha\AppData\Roaming\Python\Python312\site-packages\django\core\handlers\base.py", line 197, in _get_response
    response = wrapped_callback(request, *callback_args, **callback_kwargs)
               ^^^^^^^^^^^^^^^^^^^^^^^^^^^^^^^^^^^^^^^^^^^^^^^^^^^^^^^^^^^^
  File "C:\Users\dpsha\AppData\Roaming\Python\Python312\site-packages\django_ratelimit\decorators.py", line 27, in _wrapped
    return fn(request, *args, **kw)
           ^^^^^^^^^^^^^^^^^^^^^^^^
  File "D:\Any-Time-Event\auth1\views.py", line 328, in reset
    user=users.objects.get(email=email)
         ^^^^^^^^^^^^^^^^^^^^^^^^^^^^^^
  File "C:\Users\dpsha\AppData\Roaming\Python\Python312\site-packages\django\db\models\manager.py", line 87, in manager_method
    return getattr(self.get_queryset(), name)(*args, **kwargs)
           ^^^^^^^^^^^^^^^^^^^^^^^^^^^^^^^^^^^^^^^^^^^^^^^^^^^
  File "C:\Users\dpsha\AppData\Roaming\Python\Python312\site-packages\django\db\models\query.py", line 637, in get
    raise self.model.DoesNotExist(
auth1.models.users.DoesNotExist: users matching query does not exist.
"POST /auth/reset HTTP/1.1" 500 84515
Internal Server Error: /auth/reset
Traceback (most recent call last):
  File "D:\Any-Time-Event\auth1\views.py", line 329, in reset
    user=users.objects.get(email=email)
         ^^^^^^^^^^^^^^^^^^^^^^^^^^^^^^
  File "C:\Users\dpsha\AppData\Roaming\Python\Python312\site-packages\django\db\models\manager.py", line 87, in manager_method
    return getattr(self.get_queryset(), name)(*args, **kwargs)
           ^^^^^^^^^^^^^^^^^^^^^^^^^^^^^^^^^^^^^^^^^^^^^^^^^^^
  File "C:\Users\dpsha\AppData\Roaming\Python\Python312\site-packages\django\db\models\query.py", line 637, in get
    raise self.model.DoesNotExist(
auth1.models.users.DoesNotExist: users matching query does not exist.

During handling of the above exception, another exception occurred:

Traceback (most recent call last):
  File "C:\Users\dpsha\AppData\Roaming\Python\Python312\site-packages\django\core\handlers\exception.py", line 55, in inner
    response = get_response(request)
               ^^^^^^^^^^^^^^^^^^^^^
  File "C:\Users\dpsha\AppData\Roaming\Python\Python312\site-packages\django\core\handlers\base.py", line 197, in _get_response
    response = wrapped_callback(request, *callback_args, **callback_kwargs)
               ^^^^^^^^^^^^^^^^^^^^^^^^^^^^^^^^^^^^^^^^^^^^^^^^^^^^^^^^^^^^
  File "C:\Users\dpsha\AppData\Roaming\Python\Python312\site-packages\django_ratelimit\decorators.py", line 27, in _wrapped
    return fn(request, *args, **kw)
           ^^^^^^^^^^^^^^^^^^^^^^^^
  File "D:\Any-Time-Event\auth1\views.py", line 374, in reset
    except user.DoesNotExist:
           ^^^^
UnboundLocalError: cannot access local variable 'user' where it is not associated with a value
"POST /auth/reset HTTP/1.1" 500 88641
Internal Server Error: /auth/reset
Traceback (most recent call last):
  File "C:\Users\dpsha\AppData\Roaming\Python\Python312\site-packages\django\core\handlers\exception.py", line 55, in inner
    response = get_response(request)
               ^^^^^^^^^^^^^^^^^^^^^
  File "C:\Users\dpsha\AppData\Roaming\Python\Python312\site-packages\django\core\handlers\base.py", line 204, in _get_response
    self.check_response(response, callback)
  File "C:\Users\dpsha\AppData\Roaming\Python\Python312\site-packages\django\core\handlers\base.py", line 332, in check_response
    raise ValueError(
ValueError: The view auth1.views.reset didn't return an HttpResponse object. It returned None instead.
"GET /auth/reset HTTP/1.1" 500 70817
Internal Server Error: /auth/reset
Traceback (most recent call last):
  File "D:\Any-Time-Event\auth1\views.py", line 329, in reset
    user=users.objects.get(email=email)
         ^^^^^^^^^^^^^^^^^^^^^^^^^^^^^^
  File "C:\Users\dpsha\AppData\Roaming\Python\Python312\site-packages\django\db\models\manager.py", line 87, in manager_method
    return getattr(self.get_queryset(), name)(*args, **kwargs)
           ^^^^^^^^^^^^^^^^^^^^^^^^^^^^^^^^^^^^^^^^^^^^^^^^^^^
  File "C:\Users\dpsha\AppData\Roaming\Python\Python312\site-packages\django\db\models\query.py", line 637, in get
    raise self.model.DoesNotExist(
auth1.models.users.DoesNotExist: users matching query does not exist.

During handling of the above exception, another exception occurred:

Traceback (most recent call last):
  File "C:\Users\dpsha\AppData\Roaming\Python\Python312\site-packages\django\core\handlers\exception.py", line 55, in inner
    response = get_response(request)
               ^^^^^^^^^^^^^^^^^^^^^
  File "C:\Users\dpsha\AppData\Roaming\Python\Python312\site-packages\django\core\handlers\base.py", line 197, in _get_response
    response = wrapped_callback(request, *callback_args, **callback_kwargs)
               ^^^^^^^^^^^^^^^^^^^^^^^^^^^^^^^^^^^^^^^^^^^^^^^^^^^^^^^^^^^^
  File "C:\Users\dpsha\AppData\Roaming\Python\Python312\site-packages\django_ratelimit\decorators.py", line 27, in _wrapped
    return fn(request, *args, **kw)
           ^^^^^^^^^^^^^^^^^^^^^^^^
  File "D:\Any-Time-Event\auth1\views.py", line 374, in reset
    except user.DoesNotExist:
           ^^^^
UnboundLocalError: cannot access local variable 'user' where it is not associated with a value
"POST /auth/reset HTTP/1.1" 500 88637
Internal Server Error: /auth/resetpass
Traceback (most recent call last):
  File "C:\Users\dpsha\AppData\Roaming\Python\Python312\site-packages\django\core\handlers\exception.py", line 55, in inner
    response = get_response(request)
               ^^^^^^^^^^^^^^^^^^^^^
  File "C:\Users\dpsha\AppData\Roaming\Python\Python312\site-packages\django\core\handlers\base.py", line 204, in _get_response
    self.check_response(response, callback)
  File "C:\Users\dpsha\AppData\Roaming\Python\Python312\site-packages\django\core\handlers\base.py", line 332, in check_response
    raise ValueError(
ValueError: The view auth1.views.reset_pass didn't return an HttpResponse object. It returned None instead.
"GET /auth/resetpass?email=dpshah2307@gmail.com&key=0ntmcrzl5ekxid3XnXfaEsjHEXSsX3h5 HTTP/1.1" 500 71415
Internal Server Error: /auth/resetpass
Traceback (most recent call last):
  File "C:\Users\dpsha\AppData\Roaming\Python\Python312\site-packages\django\template\base.py", line 505, in parse
    compile_func = self.tags[command]
                   ~~~~~~~~~^^^^^^^^^
KeyError: 'static'

During handling of the above exception, another exception occurred:

Traceback (most recent call last):
  File "C:\Users\dpsha\AppData\Roaming\Python\Python312\site-packages\django\core\handlers\exception.py", line 55, in inner
    response = get_response(request)
               ^^^^^^^^^^^^^^^^^^^^^
  File "C:\Users\dpsha\AppData\Roaming\Python\Python312\site-packages\django\core\handlers\base.py", line 197, in _get_response
    response = wrapped_callback(request, *callback_args, **callback_kwargs)
               ^^^^^^^^^^^^^^^^^^^^^^^^^^^^^^^^^^^^^^^^^^^^^^^^^^^^^^^^^^^^
  File "C:\Users\dpsha\AppData\Roaming\Python\Python312\site-packages\django_ratelimit\decorators.py", line 27, in _wrapped
    return fn(request, *args, **kw)
           ^^^^^^^^^^^^^^^^^^^^^^^^
  File "D:\Any-Time-Event\auth1\views.py", line 432, in reset_pass
    return render(request, 'Reset_Password.html')
           ^^^^^^^^^^^^^^^^^^^^^^^^^^^^^^^^^^^^^^
  File "C:\Users\dpsha\AppData\Roaming\Python\Python312\site-packages\django\shortcuts.py", line 24, in render
    content = loader.render_to_string(template_name, context, request, using=using)
              ^^^^^^^^^^^^^^^^^^^^^^^^^^^^^^^^^^^^^^^^^^^^^^^^^^^^^^^^^^^^^^^^^^^^^
  File "C:\Users\dpsha\AppData\Roaming\Python\Python312\site-packages\django\template\loader.py", line 61, in render_to_string
    template = get_template(template_name, using=using)
               ^^^^^^^^^^^^^^^^^^^^^^^^^^^^^^^^^^^^^^^^
  File "C:\Users\dpsha\AppData\Roaming\Python\Python312\site-packages\django\template\loader.py", line 15, in get_template
    return engine.get_template(template_name)
           ^^^^^^^^^^^^^^^^^^^^^^^^^^^^^^^^^^
  File "C:\Users\dpsha\AppData\Roaming\Python\Python312\site-packages\django\template\backends\django.py", line 33, in get_template
    return Template(self.engine.get_template(template_name), self)
                    ^^^^^^^^^^^^^^^^^^^^^^^^^^^^^^^^^^^^^^^
  File "C:\Users\dpsha\AppData\Roaming\Python\Python312\site-packages\django\template\engine.py", line 175, in get_template
    template, origin = self.find_template(template_name)
                       ^^^^^^^^^^^^^^^^^^^^^^^^^^^^^^^^^
  File "C:\Users\dpsha\AppData\Roaming\Python\Python312\site-packages\django\template\engine.py", line 157, in find_template
    template = loader.get_template(name, skip=skip)
               ^^^^^^^^^^^^^^^^^^^^^^^^^^^^^^^^^^^^
  File "C:\Users\dpsha\AppData\Roaming\Python\Python312\site-packages\django\template\loaders\cached.py", line 57, in get_template
    template = super().get_template(template_name, skip)
               ^^^^^^^^^^^^^^^^^^^^^^^^^^^^^^^^^^^^^^^^^
  File "C:\Users\dpsha\AppData\Roaming\Python\Python312\site-packages\django\template\loaders\base.py", line 28, in get_template
    return Template(
           ^^^^^^^^^
  File "C:\Users\dpsha\AppData\Roaming\Python\Python312\site-packages\django\template\base.py", line 154, in __init__
    self.nodelist = self.compile_nodelist()
                    ^^^^^^^^^^^^^^^^^^^^^^^
  File "C:\Users\dpsha\AppData\Roaming\Python\Python312\site-packages\django\template\base.py", line 200, in compile_nodelist
    return parser.parse()
           ^^^^^^^^^^^^^^
  File "C:\Users\dpsha\AppData\Roaming\Python\Python312\site-packages\django\template\base.py", line 513, in parse
    raise self.error(token, e)
  File "C:\Users\dpsha\AppData\Roaming\Python\Python312\site-packages\django\template\base.py", line 511, in parse
    compiled_result = compile_func(self, token)
                      ^^^^^^^^^^^^^^^^^^^^^^^^^
  File "C:\Users\dpsha\AppData\Roaming\Python\Python312\site-packages\django\template\loader_tags.py", line 293, in do_extends
    nodelist = parser.parse()
               ^^^^^^^^^^^^^^
  File "C:\Users\dpsha\AppData\Roaming\Python\Python312\site-packages\django\template\base.py", line 513, in parse
    raise self.error(token, e)
  File "C:\Users\dpsha\AppData\Roaming\Python\Python312\site-packages\django\template\base.py", line 511, in parse
    compiled_result = compile_func(self, token)
                      ^^^^^^^^^^^^^^^^^^^^^^^^^
  File "C:\Users\dpsha\AppData\Roaming\Python\Python312\site-packages\django\template\loader_tags.py", line 232, in do_block
    nodelist = parser.parse(("endblock",))
               ^^^^^^^^^^^^^^^^^^^^^^^^^^^
  File "C:\Users\dpsha\AppData\Roaming\Python\Python312\site-packages\django\template\base.py", line 507, in parse
    self.invalid_block_tag(token, command, parse_until)
  File "C:\Users\dpsha\AppData\Roaming\Python\Python312\site-packages\django\template\base.py", line 558, in invalid_block_tag
    raise self.error(
django.template.exceptions.TemplateSyntaxError: Invalid block tag on line 13: 'static', expected 'endblock'. Did you forget to register or load this tag?
"GET /auth/resetpass?email=dpshah2307@gmail.com&key=78J2DsSw4pVlpx1w3UowBzj2Wey624en HTTP/1.1" 500 184716
Internal Server Error: /auth/resetpass
Traceback (most recent call last):
  File "C:\Users\dpsha\AppData\Roaming\Python\Python312\site-packages\django\template\base.py", line 505, in parse
    compile_func = self.tags[command]
                   ~~~~~~~~~^^^^^^^^^
KeyError: 'static'

During handling of the above exception, another exception occurred:

Traceback (most recent call last):
  File "C:\Users\dpsha\AppData\Roaming\Python\Python312\site-packages\django\core\handlers\exception.py", line 55, in inner
    response = get_response(request)
               ^^^^^^^^^^^^^^^^^^^^^
  File "C:\Users\dpsha\AppData\Roaming\Python\Python312\site-packages\django\core\handlers\base.py", line 197, in _get_response
    response = wrapped_callback(request, *callback_args, **callback_kwargs)
               ^^^^^^^^^^^^^^^^^^^^^^^^^^^^^^^^^^^^^^^^^^^^^^^^^^^^^^^^^^^^
  File "C:\Users\dpsha\AppData\Roaming\Python\Python312\site-packages\django_ratelimit\decorators.py", line 27, in _wrapped
    return fn(request, *args, **kw)
           ^^^^^^^^^^^^^^^^^^^^^^^^
  File "D:\Any-Time-Event\auth1\views.py", line 432, in reset_pass
    return render(request, 'Reset_Password.html')
           ^^^^^^^^^^^^^^^^^^^^^^^^^^^^^^^^^^^^^^
  File "C:\Users\dpsha\AppData\Roaming\Python\Python312\site-packages\django\shortcuts.py", line 24, in render
    content = loader.render_to_string(template_name, context, request, using=using)
              ^^^^^^^^^^^^^^^^^^^^^^^^^^^^^^^^^^^^^^^^^^^^^^^^^^^^^^^^^^^^^^^^^^^^^
  File "C:\Users\dpsha\AppData\Roaming\Python\Python312\site-packages\django\template\loader.py", line 61, in render_to_string
    template = get_template(template_name, using=using)
               ^^^^^^^^^^^^^^^^^^^^^^^^^^^^^^^^^^^^^^^^
  File "C:\Users\dpsha\AppData\Roaming\Python\Python312\site-packages\django\template\loader.py", line 15, in get_template
    return engine.get_template(template_name)
           ^^^^^^^^^^^^^^^^^^^^^^^^^^^^^^^^^^
  File "C:\Users\dpsha\AppData\Roaming\Python\Python312\site-packages\django\template\backends\django.py", line 33, in get_template
    return Template(self.engine.get_template(template_name), self)
                    ^^^^^^^^^^^^^^^^^^^^^^^^^^^^^^^^^^^^^^^
  File "C:\Users\dpsha\AppData\Roaming\Python\Python312\site-packages\django\template\engine.py", line 175, in get_template
    template, origin = self.find_template(template_name)
                       ^^^^^^^^^^^^^^^^^^^^^^^^^^^^^^^^^
  File "C:\Users\dpsha\AppData\Roaming\Python\Python312\site-packages\django\template\engine.py", line 157, in find_template
    template = loader.get_template(name, skip=skip)
               ^^^^^^^^^^^^^^^^^^^^^^^^^^^^^^^^^^^^
  File "C:\Users\dpsha\AppData\Roaming\Python\Python312\site-packages\django\template\loaders\cached.py", line 57, in get_template
    template = super().get_template(template_name, skip)
               ^^^^^^^^^^^^^^^^^^^^^^^^^^^^^^^^^^^^^^^^^
  File "C:\Users\dpsha\AppData\Roaming\Python\Python312\site-packages\django\template\loaders\base.py", line 28, in get_template
    return Template(
           ^^^^^^^^^
  File "C:\Users\dpsha\AppData\Roaming\Python\Python312\site-packages\django\template\base.py", line 154, in __init__
    self.nodelist = self.compile_nodelist()
                    ^^^^^^^^^^^^^^^^^^^^^^^
  File "C:\Users\dpsha\AppData\Roaming\Python\Python312\site-packages\django\template\base.py", line 200, in compile_nodelist
    return parser.parse()
           ^^^^^^^^^^^^^^
  File "C:\Users\dpsha\AppData\Roaming\Python\Python312\site-packages\django\template\base.py", line 513, in parse
    raise self.error(token, e)
  File "C:\Users\dpsha\AppData\Roaming\Python\Python312\site-packages\django\template\base.py", line 511, in parse
    compiled_result = compile_func(self, token)
                      ^^^^^^^^^^^^^^^^^^^^^^^^^
  File "C:\Users\dpsha\AppData\Roaming\Python\Python312\site-packages\django\template\loader_tags.py", line 293, in do_extends
    nodelist = parser.parse()
               ^^^^^^^^^^^^^^
  File "C:\Users\dpsha\AppData\Roaming\Python\Python312\site-packages\django\template\base.py", line 513, in parse
    raise self.error(token, e)
  File "C:\Users\dpsha\AppData\Roaming\Python\Python312\site-packages\django\template\base.py", line 511, in parse
    compiled_result = compile_func(self, token)
                      ^^^^^^^^^^^^^^^^^^^^^^^^^
  File "C:\Users\dpsha\AppData\Roaming\Python\Python312\site-packages\django\template\loader_tags.py", line 232, in do_block
    nodelist = parser.parse(("endblock",))
               ^^^^^^^^^^^^^^^^^^^^^^^^^^^
  File "C:\Users\dpsha\AppData\Roaming\Python\Python312\site-packages\django\template\base.py", line 507, in parse
    self.invalid_block_tag(token, command, parse_until)
  File "C:\Users\dpsha\AppData\Roaming\Python\Python312\site-packages\django\template\base.py", line 558, in invalid_block_tag
    raise self.error(
django.template.exceptions.TemplateSyntaxError: Invalid block tag on line 37: 'static', expected 'endblock'. Did you forget to register or load this tag?
"GET /auth/resetpass?email=dpshah2307@gmail.com&key=78J2DsSw4pVlpx1w3UowBzj2Wey624en HTTP/1.1" 500 179868
Internal Server Error: /auth/resetpass
Traceback (most recent call last):
  File "C:\Users\dpsha\AppData\Roaming\Python\Python312\site-packages\django\core\handlers\exception.py", line 55, in inner
    response = get_response(request)
               ^^^^^^^^^^^^^^^^^^^^^
  File "C:\Users\dpsha\AppData\Roaming\Python\Python312\site-packages\django\core\handlers\base.py", line 197, in _get_response
    response = wrapped_callback(request, *callback_args, **callback_kwargs)
               ^^^^^^^^^^^^^^^^^^^^^^^^^^^^^^^^^^^^^^^^^^^^^^^^^^^^^^^^^^^^
  File "C:\Users\dpsha\AppData\Roaming\Python\Python312\site-packages\django_ratelimit\decorators.py", line 27, in _wrapped
    return fn(request, *args, **kw)
           ^^^^^^^^^^^^^^^^^^^^^^^^
  File "D:\Any-Time-Event\auth1\views.py", line 432, in reset_pass
    return render(request, 'Reset_Password.html')
           ^^^^^^^^^^^^^^^^^^^^^^^^^^^^^^^^^^^^^^
  File "C:\Users\dpsha\AppData\Roaming\Python\Python312\site-packages\django\shortcuts.py", line 24, in render
    content = loader.render_to_string(template_name, context, request, using=using)
              ^^^^^^^^^^^^^^^^^^^^^^^^^^^^^^^^^^^^^^^^^^^^^^^^^^^^^^^^^^^^^^^^^^^^^
  File "C:\Users\dpsha\AppData\Roaming\Python\Python312\site-packages\django\template\loader.py", line 62, in render_to_string
    return template.render(context, request)
           ^^^^^^^^^^^^^^^^^^^^^^^^^^^^^^^^^
  File "C:\Users\dpsha\AppData\Roaming\Python\Python312\site-packages\django\template\backends\django.py", line 61, in render
    return self.template.render(context)
           ^^^^^^^^^^^^^^^^^^^^^^^^^^^^^
  File "C:\Users\dpsha\AppData\Roaming\Python\Python312\site-packages\django\template\base.py", line 175, in render
    return self._render(context)
           ^^^^^^^^^^^^^^^^^^^^^
  File "C:\Users\dpsha\AppData\Roaming\Python\Python312\site-packages\django\template\base.py", line 167, in _render
    return self.nodelist.render(context)
           ^^^^^^^^^^^^^^^^^^^^^^^^^^^^^
  File "C:\Users\dpsha\AppData\Roaming\Python\Python312\site-packages\django\template\base.py", line 1005, in render
    return SafeString("".join([node.render_annotated(context) for node in self]))
                               ^^^^^^^^^^^^^^^^^^^^^^^^^^^^^^
  File "C:\Users\dpsha\AppData\Roaming\Python\Python312\site-packages\django\template\base.py", line 966, in render_annotated
    return self.render(context)
           ^^^^^^^^^^^^^^^^^^^^
  File "C:\Users\dpsha\AppData\Roaming\Python\Python312\site-packages\django\template\loader_tags.py", line 157, in render
    return compiled_parent._render(context)
           ^^^^^^^^^^^^^^^^^^^^^^^^^^^^^^^^
  File "C:\Users\dpsha\AppData\Roaming\Python\Python312\site-packages\django\template\base.py", line 167, in _render
    return self.nodelist.render(context)
           ^^^^^^^^^^^^^^^^^^^^^^^^^^^^^
  File "C:\Users\dpsha\AppData\Roaming\Python\Python312\site-packages\django\template\base.py", line 1005, in render
    return SafeString("".join([node.render_annotated(context) for node in self]))
                               ^^^^^^^^^^^^^^^^^^^^^^^^^^^^^^
  File "C:\Users\dpsha\AppData\Roaming\Python\Python312\site-packages\django\template\base.py", line 966, in render_annotated
    return self.render(context)
           ^^^^^^^^^^^^^^^^^^^^
  File "C:\Users\dpsha\AppData\Roaming\Python\Python312\site-packages\django\template\loader_tags.py", line 63, in render
    result = block.nodelist.render(context)
             ^^^^^^^^^^^^^^^^^^^^^^^^^^^^^^
  File "C:\Users\dpsha\AppData\Roaming\Python\Python312\site-packages\django\template\base.py", line 1005, in render
    return SafeString("".join([node.render_annotated(context) for node in self]))
                               ^^^^^^^^^^^^^^^^^^^^^^^^^^^^^^
  File "C:\Users\dpsha\AppData\Roaming\Python\Python312\site-packages\django\template\base.py", line 966, in render_annotated
    return self.render(context)
           ^^^^^^^^^^^^^^^^^^^^
  File "C:\Users\dpsha\AppData\Roaming\Python\Python312\site-packages\django\template\defaulttags.py", line 471, in render
    url = reverse(view_name, args=args, kwargs=kwargs, current_app=current_app)
          ^^^^^^^^^^^^^^^^^^^^^^^^^^^^^^^^^^^^^^^^^^^^^^^^^^^^^^^^^^^^^^^^^^^^^
  File "C:\Users\dpsha\AppData\Roaming\Python\Python312\site-packages\django\urls\base.py", line 88, in reverse
    return resolver._reverse_with_prefix(view, prefix, *args, **kwargs)
           ^^^^^^^^^^^^^^^^^^^^^^^^^^^^^^^^^^^^^^^^^^^^^^^^^^^^^^^^^^^^
  File "C:\Users\dpsha\AppData\Roaming\Python\Python312\site-packages\django\urls\resolvers.py", line 828, in _reverse_with_prefix
    raise NoReverseMatch(msg)
django.urls.exceptions.NoReverseMatch: Reverse for 'reset_pass' not found. 'reset_pass' is not a valid view function or pattern name.
"GET /auth/resetpass?email=dpshah2307@gmail.com&key=78J2DsSw4pVlpx1w3UowBzj2Wey624en HTTP/1.1" 500 156829
Internal Server Error: /auth/resetpass
Traceback (most recent call last):
  File "C:\Users\dpsha\AppData\Roaming\Python\Python312\site-packages\django\core\handlers\exception.py", line 55, in inner
    response = get_response(request)
               ^^^^^^^^^^^^^^^^^^^^^
  File "C:\Users\dpsha\AppData\Roaming\Python\Python312\site-packages\django\core\handlers\base.py", line 197, in _get_response
    response = wrapped_callback(request, *callback_args, **callback_kwargs)
               ^^^^^^^^^^^^^^^^^^^^^^^^^^^^^^^^^^^^^^^^^^^^^^^^^^^^^^^^^^^^
  File "C:\Users\dpsha\AppData\Roaming\Python\Python312\site-packages\django_ratelimit\decorators.py", line 27, in _wrapped
    return fn(request, *args, **kw)
           ^^^^^^^^^^^^^^^^^^^^^^^^
  File "D:\Any-Time-Event\auth1\views.py", line 412, in reset_pass
    user = users.objects.get(email=email)
                                   ^^^^^
UnboundLocalError: cannot access local variable 'email' where it is not associated with a value
"POST /auth/resetpass HTTP/1.1" 500 76492
Internal Server Error: /auth/resetpass
Traceback (most recent call last):
  File "C:\Users\dpsha\AppData\Roaming\Python\Python312\site-packages\django\core\handlers\exception.py", line 55, in inner
    response = get_response(request)
               ^^^^^^^^^^^^^^^^^^^^^
  File "C:\Users\dpsha\AppData\Roaming\Python\Python312\site-packages\django\core\handlers\base.py", line 197, in _get_response
    response = wrapped_callback(request, *callback_args, **callback_kwargs)
               ^^^^^^^^^^^^^^^^^^^^^^^^^^^^^^^^^^^^^^^^^^^^^^^^^^^^^^^^^^^^
  File "C:\Users\dpsha\AppData\Roaming\Python\Python312\site-packages\django_ratelimit\decorators.py", line 27, in _wrapped
    return fn(request, *args, **kw)
           ^^^^^^^^^^^^^^^^^^^^^^^^
  File "D:\Any-Time-Event\auth1\views.py", line 417, in reset_pass
    f = Fernet(key)
        ^^^^^^^^^^^
  File "C:\Users\dpsha\AppData\Roaming\Python\Python312\site-packages\cryptography\fernet.py", line 40, in __init__
    raise ValueError(
ValueError: Fernet key must be 32 url-safe base64-encoded bytes.
"POST /auth/resetpass HTTP/1.1" 500 80881
Internal Server Error: /auth/resetpass
Traceback (most recent call last):
  File "C:\Users\dpsha\AppData\Roaming\Python\Python312\site-packages\django\core\handlers\exception.py", line 55, in inner
    response = get_response(request)
               ^^^^^^^^^^^^^^^^^^^^^
  File "C:\Users\dpsha\AppData\Roaming\Python\Python312\site-packages\django\core\handlers\base.py", line 197, in _get_response
    response = wrapped_callback(request, *callback_args, **callback_kwargs)
               ^^^^^^^^^^^^^^^^^^^^^^^^^^^^^^^^^^^^^^^^^^^^^^^^^^^^^^^^^^^^
  File "C:\Users\dpsha\AppData\Roaming\Python\Python312\site-packages\django_ratelimit\decorators.py", line 27, in _wrapped
    return fn(request, *args, **kw)
           ^^^^^^^^^^^^^^^^^^^^^^^^
  File "D:\Any-Time-Event\auth1\views.py", line 416, in reset_pass
    key = key()
          ^^^
UnboundLocalError: cannot access local variable 'key' where it is not associated with a value
"POST /auth/resetpass HTTP/1.1" 500 76897
Internal Server Error: /auth/resetpass
Traceback (most recent call last):
  File "C:\Users\dpsha\AppData\Roaming\Python\Python312\site-packages\django\core\handlers\exception.py", line 55, in inner
    response = get_response(request)
               ^^^^^^^^^^^^^^^^^^^^^
  File "C:\Users\dpsha\AppData\Roaming\Python\Python312\site-packages\django\core\handlers\base.py", line 197, in _get_response
    response = wrapped_callback(request, *callback_args, **callback_kwargs)
               ^^^^^^^^^^^^^^^^^^^^^^^^^^^^^^^^^^^^^^^^^^^^^^^^^^^^^^^^^^^^
  File "C:\Users\dpsha\AppData\Roaming\Python\Python312\site-packages\django_ratelimit\decorators.py", line 27, in _wrapped
    return fn(request, *args, **kw)
           ^^^^^^^^^^^^^^^^^^^^^^^^
  File "D:\Any-Time-Event\auth1\views.py", line 416, in reset_pass
    key1 = key()
           ^^^
UnboundLocalError: cannot access local variable 'key' where it is not associated with a value
"POST /auth/resetpass HTTP/1.1" 500 76903
Internal Server Error: /auth/resetpass
Traceback (most recent call last):
  File "C:\Users\dpsha\AppData\Roaming\Python\Python312\site-packages\django\core\handlers\exception.py", line 55, in inner
    response = get_response(request)
               ^^^^^^^^^^^^^^^^^^^^^
  File "C:\Users\dpsha\AppData\Roaming\Python\Python312\site-packages\django\core\handlers\base.py", line 197, in _get_response
    response = wrapped_callback(request, *callback_args, **callback_kwargs)
               ^^^^^^^^^^^^^^^^^^^^^^^^^^^^^^^^^^^^^^^^^^^^^^^^^^^^^^^^^^^^
  File "C:\Users\dpsha\AppData\Roaming\Python\Python312\site-packages\django_ratelimit\decorators.py", line 27, in _wrapped
    return fn(request, *args, **kw)
           ^^^^^^^^^^^^^^^^^^^^^^^^
  File "D:\Any-Time-Event\auth1\views.py", line 416, in reset_pass
    key1 = key()
           ^^^
UnboundLocalError: cannot access local variable 'key' where it is not associated with a value
"POST /auth/resetpass HTTP/1.1" 500 76903
Internal Server Error: /auth/resetpass
Traceback (most recent call last):
  File "C:\Users\dpsha\AppData\Roaming\Python\Python312\site-packages\django\core\handlers\exception.py", line 55, in inner
    response = get_response(request)
               ^^^^^^^^^^^^^^^^^^^^^
  File "C:\Users\dpsha\AppData\Roaming\Python\Python312\site-packages\django\core\handlers\base.py", line 197, in _get_response
    response = wrapped_callback(request, *callback_args, **callback_kwargs)
               ^^^^^^^^^^^^^^^^^^^^^^^^^^^^^^^^^^^^^^^^^^^^^^^^^^^^^^^^^^^^
  File "C:\Users\dpsha\AppData\Roaming\Python\Python312\site-packages\django_ratelimit\decorators.py", line 27, in _wrapped
    return fn(request, *args, **kw)
           ^^^^^^^^^^^^^^^^^^^^^^^^
  File "D:\Any-Time-Event\auth1\views.py", line 416, in reset_pass
    key1 = key()
           ^^^
UnboundLocalError: cannot access local variable 'key' where it is not associated with a value
"POST /auth/resetpass HTTP/1.1" 500 76903
Internal Server Error: /auth/validate
Traceback (most recent call last):
  File "C:\Users\dpsha\AppData\Roaming\Python\Python312\site-packages\django\core\handlers\exception.py", line 55, in inner
    response = get_response(request)
               ^^^^^^^^^^^^^^^^^^^^^
  File "C:\Users\dpsha\AppData\Roaming\Python\Python312\site-packages\django\core\handlers\base.py", line 197, in _get_response
    response = wrapped_callback(request, *callback_args, **callback_kwargs)
               ^^^^^^^^^^^^^^^^^^^^^^^^^^^^^^^^^^^^^^^^^^^^^^^^^^^^^^^^^^^^
  File "C:\Users\dpsha\AppData\Roaming\Python\Python312\site-packages\django_ratelimit\decorators.py", line 27, in _wrapped
    return fn(request, *args, **kw)
           ^^^^^^^^^^^^^^^^^^^^^^^^
  File "D:\Any-Time-Event\auth1\views.py", line 55, in validate
    return render(request, 'validate.html')
           ^^^^^^^^^^^^^^^^^^^^^^^^^^^^^^^^
  File "C:\Users\dpsha\AppData\Roaming\Python\Python312\site-packages\django\shortcuts.py", line 24, in render
    content = loader.render_to_string(template_name, context, request, using=using)
              ^^^^^^^^^^^^^^^^^^^^^^^^^^^^^^^^^^^^^^^^^^^^^^^^^^^^^^^^^^^^^^^^^^^^^
  File "C:\Users\dpsha\AppData\Roaming\Python\Python312\site-packages\django\template\loader.py", line 62, in render_to_string
    return template.render(context, request)
           ^^^^^^^^^^^^^^^^^^^^^^^^^^^^^^^^^
  File "C:\Users\dpsha\AppData\Roaming\Python\Python312\site-packages\django\template\backends\django.py", line 61, in render
    return self.template.render(context)
           ^^^^^^^^^^^^^^^^^^^^^^^^^^^^^
  File "C:\Users\dpsha\AppData\Roaming\Python\Python312\site-packages\django\template\base.py", line 175, in render
    return self._render(context)
           ^^^^^^^^^^^^^^^^^^^^^
  File "C:\Users\dpsha\AppData\Roaming\Python\Python312\site-packages\django\template\base.py", line 167, in _render
    return self.nodelist.render(context)
           ^^^^^^^^^^^^^^^^^^^^^^^^^^^^^
  File "C:\Users\dpsha\AppData\Roaming\Python\Python312\site-packages\django\template\base.py", line 1005, in render
    return SafeString("".join([node.render_annotated(context) for node in self]))
                               ^^^^^^^^^^^^^^^^^^^^^^^^^^^^^^
  File "C:\Users\dpsha\AppData\Roaming\Python\Python312\site-packages\django\template\base.py", line 966, in render_annotated
    return self.render(context)
           ^^^^^^^^^^^^^^^^^^^^
  File "C:\Users\dpsha\AppData\Roaming\Python\Python312\site-packages\django\template\loader_tags.py", line 157, in render
    return compiled_parent._render(context)
           ^^^^^^^^^^^^^^^^^^^^^^^^^^^^^^^^
  File "C:\Users\dpsha\AppData\Roaming\Python\Python312\site-packages\django\template\base.py", line 167, in _render
    return self.nodelist.render(context)
           ^^^^^^^^^^^^^^^^^^^^^^^^^^^^^
  File "C:\Users\dpsha\AppData\Roaming\Python\Python312\site-packages\django\template\base.py", line 1005, in render
    return SafeString("".join([node.render_annotated(context) for node in self]))
                               ^^^^^^^^^^^^^^^^^^^^^^^^^^^^^^
  File "C:\Users\dpsha\AppData\Roaming\Python\Python312\site-packages\django\template\base.py", line 966, in render_annotated
    return self.render(context)
           ^^^^^^^^^^^^^^^^^^^^
  File "C:\Users\dpsha\AppData\Roaming\Python\Python312\site-packages\django\template\loader_tags.py", line 63, in render
    result = block.nodelist.render(context)
             ^^^^^^^^^^^^^^^^^^^^^^^^^^^^^^
  File "C:\Users\dpsha\AppData\Roaming\Python\Python312\site-packages\django\template\base.py", line 1005, in render
    return SafeString("".join([node.render_annotated(context) for node in self]))
                               ^^^^^^^^^^^^^^^^^^^^^^^^^^^^^^
  File "C:\Users\dpsha\AppData\Roaming\Python\Python312\site-packages\django\template\base.py", line 966, in render_annotated
    return self.render(context)
           ^^^^^^^^^^^^^^^^^^^^
  File "C:\Users\dpsha\AppData\Roaming\Python\Python312\site-packages\django\template\defaulttags.py", line 471, in render
    url = reverse(view_name, args=args, kwargs=kwargs, current_app=current_app)
          ^^^^^^^^^^^^^^^^^^^^^^^^^^^^^^^^^^^^^^^^^^^^^^^^^^^^^^^^^^^^^^^^^^^^^
  File "C:\Users\dpsha\AppData\Roaming\Python\Python312\site-packages\django\urls\base.py", line 88, in reverse
    return resolver._reverse_with_prefix(view, prefix, *args, **kwargs)
           ^^^^^^^^^^^^^^^^^^^^^^^^^^^^^^^^^^^^^^^^^^^^^^^^^^^^^^^^^^^^
  File "C:\Users\dpsha\AppData\Roaming\Python\Python312\site-packages\django\urls\resolvers.py", line 828, in _reverse_with_prefix
    raise NoReverseMatch(msg)
django.urls.exceptions.NoReverseMatch: Reverse for '/auth/validate' not found. '/auth/validate' is not a valid view function or pattern name.
"GET /auth/validate? HTTP/1.1" 500 154538
Internal Server Error: /auth/validate
Traceback (most recent call last):
  File "C:\Users\dpsha\AppData\Roaming\Python\Python312\site-packages\django\core\handlers\exception.py", line 55, in inner
    response = get_response(request)
               ^^^^^^^^^^^^^^^^^^^^^
  File "C:\Users\dpsha\AppData\Roaming\Python\Python312\site-packages\django\core\handlers\base.py", line 197, in _get_response
    response = wrapped_callback(request, *callback_args, **callback_kwargs)
               ^^^^^^^^^^^^^^^^^^^^^^^^^^^^^^^^^^^^^^^^^^^^^^^^^^^^^^^^^^^^
  File "C:\Users\dpsha\AppData\Roaming\Python\Python312\site-packages\django_ratelimit\decorators.py", line 27, in _wrapped
    return fn(request, *args, **kw)
           ^^^^^^^^^^^^^^^^^^^^^^^^
  File "D:\Any-Time-Event\auth1\views.py", line 55, in validate
    return render(request, 'validate.html')
           ^^^^^^^^^^^^^^^^^^^^^^^^^^^^^^^^
  File "C:\Users\dpsha\AppData\Roaming\Python\Python312\site-packages\django\shortcuts.py", line 24, in render
    content = loader.render_to_string(template_name, context, request, using=using)
              ^^^^^^^^^^^^^^^^^^^^^^^^^^^^^^^^^^^^^^^^^^^^^^^^^^^^^^^^^^^^^^^^^^^^^
  File "C:\Users\dpsha\AppData\Roaming\Python\Python312\site-packages\django\template\loader.py", line 62, in render_to_string
    return template.render(context, request)
           ^^^^^^^^^^^^^^^^^^^^^^^^^^^^^^^^^
  File "C:\Users\dpsha\AppData\Roaming\Python\Python312\site-packages\django\template\backends\django.py", line 61, in render
    return self.template.render(context)
           ^^^^^^^^^^^^^^^^^^^^^^^^^^^^^
  File "C:\Users\dpsha\AppData\Roaming\Python\Python312\site-packages\django\template\base.py", line 175, in render
    return self._render(context)
           ^^^^^^^^^^^^^^^^^^^^^
  File "C:\Users\dpsha\AppData\Roaming\Python\Python312\site-packages\django\template\base.py", line 167, in _render
    return self.nodelist.render(context)
           ^^^^^^^^^^^^^^^^^^^^^^^^^^^^^
  File "C:\Users\dpsha\AppData\Roaming\Python\Python312\site-packages\django\template\base.py", line 1005, in render
    return SafeString("".join([node.render_annotated(context) for node in self]))
                               ^^^^^^^^^^^^^^^^^^^^^^^^^^^^^^
  File "C:\Users\dpsha\AppData\Roaming\Python\Python312\site-packages\django\template\base.py", line 966, in render_annotated
    return self.render(context)
           ^^^^^^^^^^^^^^^^^^^^
  File "C:\Users\dpsha\AppData\Roaming\Python\Python312\site-packages\django\template\loader_tags.py", line 157, in render
    return compiled_parent._render(context)
           ^^^^^^^^^^^^^^^^^^^^^^^^^^^^^^^^
  File "C:\Users\dpsha\AppData\Roaming\Python\Python312\site-packages\django\template\base.py", line 167, in _render
    return self.nodelist.render(context)
           ^^^^^^^^^^^^^^^^^^^^^^^^^^^^^
  File "C:\Users\dpsha\AppData\Roaming\Python\Python312\site-packages\django\template\base.py", line 1005, in render
    return SafeString("".join([node.render_annotated(context) for node in self]))
                               ^^^^^^^^^^^^^^^^^^^^^^^^^^^^^^
  File "C:\Users\dpsha\AppData\Roaming\Python\Python312\site-packages\django\template\base.py", line 966, in render_annotated
    return self.render(context)
           ^^^^^^^^^^^^^^^^^^^^
  File "C:\Users\dpsha\AppData\Roaming\Python\Python312\site-packages\django\template\loader_tags.py", line 63, in render
    result = block.nodelist.render(context)
             ^^^^^^^^^^^^^^^^^^^^^^^^^^^^^^
  File "C:\Users\dpsha\AppData\Roaming\Python\Python312\site-packages\django\template\base.py", line 1005, in render
    return SafeString("".join([node.render_annotated(context) for node in self]))
                               ^^^^^^^^^^^^^^^^^^^^^^^^^^^^^^
  File "C:\Users\dpsha\AppData\Roaming\Python\Python312\site-packages\django\template\base.py", line 966, in render_annotated
    return self.render(context)
           ^^^^^^^^^^^^^^^^^^^^
  File "C:\Users\dpsha\AppData\Roaming\Python\Python312\site-packages\django\template\defaulttags.py", line 471, in render
    url = reverse(view_name, args=args, kwargs=kwargs, current_app=current_app)
          ^^^^^^^^^^^^^^^^^^^^^^^^^^^^^^^^^^^^^^^^^^^^^^^^^^^^^^^^^^^^^^^^^^^^^
  File "C:\Users\dpsha\AppData\Roaming\Python\Python312\site-packages\django\urls\base.py", line 88, in reverse
    return resolver._reverse_with_prefix(view, prefix, *args, **kwargs)
           ^^^^^^^^^^^^^^^^^^^^^^^^^^^^^^^^^^^^^^^^^^^^^^^^^^^^^^^^^^^^
  File "C:\Users\dpsha\AppData\Roaming\Python\Python312\site-packages\django\urls\resolvers.py", line 828, in _reverse_with_prefix
    raise NoReverseMatch(msg)
django.urls.exceptions.NoReverseMatch: Reverse for '/auth/validate' not found. '/auth/validate' is not a valid view function or pattern name.
"GET /auth/validate? HTTP/1.1" 500 154538
